2025-02-19 11:18:12,772 ERROR scheduler Exception in Enqueue Events for Site erp-psd-demo
Traceback (most recent call last):
  File "env/lib/python3.10/site-packages/pymysql/connections.py", line 649, in connect
    sock = socket.create_connection(
  File "/usr/lib/python3.10/socket.py", line 857, in create_connection
    raise err
  File "/usr/lib/python3.10/socket.py", line 845, in create_connection
    sock.connect(sa)
ConnectionRefusedError: [Errno 111] Connection refused

During handling of the above exception, another exception occurred:

Traceback (most recent call last):
  File "apps/frappe/frappe/utils/scheduler.py", line 75, in enqueue_events_for_site
    if is_scheduler_inactive():
  File "apps/frappe/frappe/utils/scheduler.py", line 119, in is_scheduler_inactive
    if is_scheduler_disabled(verbose=verbose):
  File "apps/frappe/frappe/utils/scheduler.py", line 132, in is_scheduler_disabled
    frappe.db.get_single_value("System Settings", "enable_scheduler")
  File "apps/frappe/frappe/database/database.py", line 859, in get_single_value
    ).run()
  File "apps/frappe/frappe/query_builder/utils.py", line 87, in execute_query
    result = frappe.db.sql(query, params, *args, **kwargs)  # nosemgrep
  File "apps/frappe/frappe/database/database.py", line 221, in sql
    self.connect()
  File "apps/frappe/frappe/database/database.py", line 126, in connect
    self._conn: "MariadbConnection" | "PostgresConnection" = self.get_connection()
  File "apps/frappe/frappe/database/mariadb/database.py", line 103, in get_connection
    conn = self._get_connection()
  File "apps/frappe/frappe/database/mariadb/database.py", line 109, in _get_connection
    return self.create_connection()
  File "apps/frappe/frappe/database/mariadb/database.py", line 112, in create_connection
    return pymysql.connect(**self.get_connection_settings())
  File "env/lib/python3.10/site-packages/pymysql/connections.py", line 361, in __init__
    self.connect()
  File "env/lib/python3.10/site-packages/pymysql/connections.py", line 716, in connect
    raise exc
pymysql.err.OperationalError: (2003, "Can't connect to MySQL server on '127.0.0.1' ([Errno 111] Connection refused)")

2025-02-19 11:19:12,874 ERROR scheduler Exception in Enqueue Events for Site erp-psd-demo
Traceback (most recent call last):
  File "env/lib/python3.10/site-packages/pymysql/connections.py", line 649, in connect
    sock = socket.create_connection(
  File "/usr/lib/python3.10/socket.py", line 857, in create_connection
    raise err
  File "/usr/lib/python3.10/socket.py", line 845, in create_connection
    sock.connect(sa)
ConnectionRefusedError: [Errno 111] Connection refused

During handling of the above exception, another exception occurred:

Traceback (most recent call last):
  File "apps/frappe/frappe/utils/scheduler.py", line 75, in enqueue_events_for_site
    if is_scheduler_inactive():
  File "apps/frappe/frappe/utils/scheduler.py", line 119, in is_scheduler_inactive
    if is_scheduler_disabled(verbose=verbose):
  File "apps/frappe/frappe/utils/scheduler.py", line 132, in is_scheduler_disabled
    frappe.db.get_single_value("System Settings", "enable_scheduler")
  File "apps/frappe/frappe/database/database.py", line 859, in get_single_value
    ).run()
  File "apps/frappe/frappe/query_builder/utils.py", line 87, in execute_query
    result = frappe.db.sql(query, params, *args, **kwargs)  # nosemgrep
  File "apps/frappe/frappe/database/database.py", line 221, in sql
    self.connect()
  File "apps/frappe/frappe/database/database.py", line 126, in connect
    self._conn: "MariadbConnection" | "PostgresConnection" = self.get_connection()
  File "apps/frappe/frappe/database/mariadb/database.py", line 103, in get_connection
    conn = self._get_connection()
  File "apps/frappe/frappe/database/mariadb/database.py", line 109, in _get_connection
    return self.create_connection()
  File "apps/frappe/frappe/database/mariadb/database.py", line 112, in create_connection
    return pymysql.connect(**self.get_connection_settings())
  File "env/lib/python3.10/site-packages/pymysql/connections.py", line 361, in __init__
    self.connect()
  File "env/lib/python3.10/site-packages/pymysql/connections.py", line 716, in connect
    raise exc
pymysql.err.OperationalError: (2003, "Can't connect to MySQL server on '127.0.0.1' ([Errno 111] Connection refused)")

2025-02-19 11:20:12,974 ERROR scheduler Exception in Enqueue Events for Site erp-psd-demo
Traceback (most recent call last):
  File "env/lib/python3.10/site-packages/pymysql/connections.py", line 649, in connect
    sock = socket.create_connection(
  File "/usr/lib/python3.10/socket.py", line 857, in create_connection
    raise err
  File "/usr/lib/python3.10/socket.py", line 845, in create_connection
    sock.connect(sa)
ConnectionRefusedError: [Errno 111] Connection refused

During handling of the above exception, another exception occurred:

Traceback (most recent call last):
  File "apps/frappe/frappe/utils/scheduler.py", line 75, in enqueue_events_for_site
    if is_scheduler_inactive():
  File "apps/frappe/frappe/utils/scheduler.py", line 119, in is_scheduler_inactive
    if is_scheduler_disabled(verbose=verbose):
  File "apps/frappe/frappe/utils/scheduler.py", line 132, in is_scheduler_disabled
    frappe.db.get_single_value("System Settings", "enable_scheduler")
  File "apps/frappe/frappe/database/database.py", line 859, in get_single_value
    ).run()
  File "apps/frappe/frappe/query_builder/utils.py", line 87, in execute_query
    result = frappe.db.sql(query, params, *args, **kwargs)  # nosemgrep
  File "apps/frappe/frappe/database/database.py", line 221, in sql
    self.connect()
  File "apps/frappe/frappe/database/database.py", line 126, in connect
    self._conn: "MariadbConnection" | "PostgresConnection" = self.get_connection()
  File "apps/frappe/frappe/database/mariadb/database.py", line 103, in get_connection
    conn = self._get_connection()
  File "apps/frappe/frappe/database/mariadb/database.py", line 109, in _get_connection
    return self.create_connection()
  File "apps/frappe/frappe/database/mariadb/database.py", line 112, in create_connection
    return pymysql.connect(**self.get_connection_settings())
  File "env/lib/python3.10/site-packages/pymysql/connections.py", line 361, in __init__
    self.connect()
  File "env/lib/python3.10/site-packages/pymysql/connections.py", line 716, in connect
    raise exc
pymysql.err.OperationalError: (2003, "Can't connect to MySQL server on '127.0.0.1' ([Errno 111] Connection refused)")

2025-02-19 11:21:13,074 ERROR scheduler Exception in Enqueue Events for Site erp-psd-demo
Traceback (most recent call last):
  File "env/lib/python3.10/site-packages/pymysql/connections.py", line 649, in connect
    sock = socket.create_connection(
  File "/usr/lib/python3.10/socket.py", line 857, in create_connection
    raise err
  File "/usr/lib/python3.10/socket.py", line 845, in create_connection
    sock.connect(sa)
ConnectionRefusedError: [Errno 111] Connection refused

During handling of the above exception, another exception occurred:

Traceback (most recent call last):
  File "apps/frappe/frappe/utils/scheduler.py", line 75, in enqueue_events_for_site
    if is_scheduler_inactive():
  File "apps/frappe/frappe/utils/scheduler.py", line 119, in is_scheduler_inactive
    if is_scheduler_disabled(verbose=verbose):
  File "apps/frappe/frappe/utils/scheduler.py", line 132, in is_scheduler_disabled
    frappe.db.get_single_value("System Settings", "enable_scheduler")
  File "apps/frappe/frappe/database/database.py", line 859, in get_single_value
    ).run()
  File "apps/frappe/frappe/query_builder/utils.py", line 87, in execute_query
    result = frappe.db.sql(query, params, *args, **kwargs)  # nosemgrep
  File "apps/frappe/frappe/database/database.py", line 221, in sql
    self.connect()
  File "apps/frappe/frappe/database/database.py", line 126, in connect
    self._conn: "MariadbConnection" | "PostgresConnection" = self.get_connection()
  File "apps/frappe/frappe/database/mariadb/database.py", line 103, in get_connection
    conn = self._get_connection()
  File "apps/frappe/frappe/database/mariadb/database.py", line 109, in _get_connection
    return self.create_connection()
  File "apps/frappe/frappe/database/mariadb/database.py", line 112, in create_connection
    return pymysql.connect(**self.get_connection_settings())
  File "env/lib/python3.10/site-packages/pymysql/connections.py", line 361, in __init__
    self.connect()
  File "env/lib/python3.10/site-packages/pymysql/connections.py", line 716, in connect
    raise exc
pymysql.err.OperationalError: (2003, "Can't connect to MySQL server on '127.0.0.1' ([Errno 111] Connection refused)")

2025-02-19 11:22:13,176 ERROR scheduler Exception in Enqueue Events for Site erp-psd-demo
Traceback (most recent call last):
  File "env/lib/python3.10/site-packages/pymysql/connections.py", line 649, in connect
    sock = socket.create_connection(
  File "/usr/lib/python3.10/socket.py", line 857, in create_connection
    raise err
  File "/usr/lib/python3.10/socket.py", line 845, in create_connection
    sock.connect(sa)
ConnectionRefusedError: [Errno 111] Connection refused

During handling of the above exception, another exception occurred:

Traceback (most recent call last):
  File "apps/frappe/frappe/utils/scheduler.py", line 75, in enqueue_events_for_site
    if is_scheduler_inactive():
  File "apps/frappe/frappe/utils/scheduler.py", line 119, in is_scheduler_inactive
    if is_scheduler_disabled(verbose=verbose):
  File "apps/frappe/frappe/utils/scheduler.py", line 132, in is_scheduler_disabled
    frappe.db.get_single_value("System Settings", "enable_scheduler")
  File "apps/frappe/frappe/database/database.py", line 859, in get_single_value
    ).run()
  File "apps/frappe/frappe/query_builder/utils.py", line 87, in execute_query
    result = frappe.db.sql(query, params, *args, **kwargs)  # nosemgrep
  File "apps/frappe/frappe/database/database.py", line 221, in sql
    self.connect()
  File "apps/frappe/frappe/database/database.py", line 126, in connect
    self._conn: "MariadbConnection" | "PostgresConnection" = self.get_connection()
  File "apps/frappe/frappe/database/mariadb/database.py", line 103, in get_connection
    conn = self._get_connection()
  File "apps/frappe/frappe/database/mariadb/database.py", line 109, in _get_connection
    return self.create_connection()
  File "apps/frappe/frappe/database/mariadb/database.py", line 112, in create_connection
    return pymysql.connect(**self.get_connection_settings())
  File "env/lib/python3.10/site-packages/pymysql/connections.py", line 361, in __init__
    self.connect()
  File "env/lib/python3.10/site-packages/pymysql/connections.py", line 716, in connect
    raise exc
pymysql.err.OperationalError: (2003, "Can't connect to MySQL server on '127.0.0.1' ([Errno 111] Connection refused)")

2025-02-19 11:23:13,278 ERROR scheduler Exception in Enqueue Events for Site erp-psd-demo
Traceback (most recent call last):
  File "env/lib/python3.10/site-packages/pymysql/connections.py", line 649, in connect
    sock = socket.create_connection(
  File "/usr/lib/python3.10/socket.py", line 857, in create_connection
    raise err
  File "/usr/lib/python3.10/socket.py", line 845, in create_connection
    sock.connect(sa)
ConnectionRefusedError: [Errno 111] Connection refused

During handling of the above exception, another exception occurred:

Traceback (most recent call last):
  File "apps/frappe/frappe/utils/scheduler.py", line 75, in enqueue_events_for_site
    if is_scheduler_inactive():
  File "apps/frappe/frappe/utils/scheduler.py", line 119, in is_scheduler_inactive
    if is_scheduler_disabled(verbose=verbose):
  File "apps/frappe/frappe/utils/scheduler.py", line 132, in is_scheduler_disabled
    frappe.db.get_single_value("System Settings", "enable_scheduler")
  File "apps/frappe/frappe/database/database.py", line 859, in get_single_value
    ).run()
  File "apps/frappe/frappe/query_builder/utils.py", line 87, in execute_query
    result = frappe.db.sql(query, params, *args, **kwargs)  # nosemgrep
  File "apps/frappe/frappe/database/database.py", line 221, in sql
    self.connect()
  File "apps/frappe/frappe/database/database.py", line 126, in connect
    self._conn: "MariadbConnection" | "PostgresConnection" = self.get_connection()
  File "apps/frappe/frappe/database/mariadb/database.py", line 103, in get_connection
    conn = self._get_connection()
  File "apps/frappe/frappe/database/mariadb/database.py", line 109, in _get_connection
    return self.create_connection()
  File "apps/frappe/frappe/database/mariadb/database.py", line 112, in create_connection
    return pymysql.connect(**self.get_connection_settings())
  File "env/lib/python3.10/site-packages/pymysql/connections.py", line 361, in __init__
    self.connect()
  File "env/lib/python3.10/site-packages/pymysql/connections.py", line 716, in connect
    raise exc
pymysql.err.OperationalError: (2003, "Can't connect to MySQL server on '127.0.0.1' ([Errno 111] Connection refused)")

2025-02-19 11:24:13,377 ERROR scheduler Exception in Enqueue Events for Site erp-psd-demo
Traceback (most recent call last):
  File "env/lib/python3.10/site-packages/pymysql/connections.py", line 649, in connect
    sock = socket.create_connection(
  File "/usr/lib/python3.10/socket.py", line 857, in create_connection
    raise err
  File "/usr/lib/python3.10/socket.py", line 845, in create_connection
    sock.connect(sa)
ConnectionRefusedError: [Errno 111] Connection refused

During handling of the above exception, another exception occurred:

Traceback (most recent call last):
  File "apps/frappe/frappe/utils/scheduler.py", line 75, in enqueue_events_for_site
    if is_scheduler_inactive():
  File "apps/frappe/frappe/utils/scheduler.py", line 119, in is_scheduler_inactive
    if is_scheduler_disabled(verbose=verbose):
  File "apps/frappe/frappe/utils/scheduler.py", line 132, in is_scheduler_disabled
    frappe.db.get_single_value("System Settings", "enable_scheduler")
  File "apps/frappe/frappe/database/database.py", line 859, in get_single_value
    ).run()
  File "apps/frappe/frappe/query_builder/utils.py", line 87, in execute_query
    result = frappe.db.sql(query, params, *args, **kwargs)  # nosemgrep
  File "apps/frappe/frappe/database/database.py", line 221, in sql
    self.connect()
  File "apps/frappe/frappe/database/database.py", line 126, in connect
    self._conn: "MariadbConnection" | "PostgresConnection" = self.get_connection()
  File "apps/frappe/frappe/database/mariadb/database.py", line 103, in get_connection
    conn = self._get_connection()
  File "apps/frappe/frappe/database/mariadb/database.py", line 109, in _get_connection
    return self.create_connection()
  File "apps/frappe/frappe/database/mariadb/database.py", line 112, in create_connection
    return pymysql.connect(**self.get_connection_settings())
  File "env/lib/python3.10/site-packages/pymysql/connections.py", line 361, in __init__
    self.connect()
  File "env/lib/python3.10/site-packages/pymysql/connections.py", line 716, in connect
    raise exc
pymysql.err.OperationalError: (2003, "Can't connect to MySQL server on '127.0.0.1' ([Errno 111] Connection refused)")

2025-02-19 11:25:13,462 ERROR scheduler Exception in Enqueue Events for Site erp-psd-demo
Traceback (most recent call last):
  File "env/lib/python3.10/site-packages/pymysql/connections.py", line 649, in connect
    sock = socket.create_connection(
  File "/usr/lib/python3.10/socket.py", line 857, in create_connection
    raise err
  File "/usr/lib/python3.10/socket.py", line 845, in create_connection
    sock.connect(sa)
ConnectionRefusedError: [Errno 111] Connection refused

During handling of the above exception, another exception occurred:

Traceback (most recent call last):
  File "apps/frappe/frappe/utils/scheduler.py", line 75, in enqueue_events_for_site
    if is_scheduler_inactive():
  File "apps/frappe/frappe/utils/scheduler.py", line 119, in is_scheduler_inactive
    if is_scheduler_disabled(verbose=verbose):
  File "apps/frappe/frappe/utils/scheduler.py", line 132, in is_scheduler_disabled
    frappe.db.get_single_value("System Settings", "enable_scheduler")
  File "apps/frappe/frappe/database/database.py", line 859, in get_single_value
    ).run()
  File "apps/frappe/frappe/query_builder/utils.py", line 87, in execute_query
    result = frappe.db.sql(query, params, *args, **kwargs)  # nosemgrep
  File "apps/frappe/frappe/database/database.py", line 221, in sql
    self.connect()
  File "apps/frappe/frappe/database/database.py", line 126, in connect
    self._conn: "MariadbConnection" | "PostgresConnection" = self.get_connection()
  File "apps/frappe/frappe/database/mariadb/database.py", line 103, in get_connection
    conn = self._get_connection()
  File "apps/frappe/frappe/database/mariadb/database.py", line 109, in _get_connection
    return self.create_connection()
  File "apps/frappe/frappe/database/mariadb/database.py", line 112, in create_connection
    return pymysql.connect(**self.get_connection_settings())
  File "env/lib/python3.10/site-packages/pymysql/connections.py", line 361, in __init__
    self.connect()
  File "env/lib/python3.10/site-packages/pymysql/connections.py", line 716, in connect
    raise exc
pymysql.err.OperationalError: (2003, "Can't connect to MySQL server on '127.0.0.1' ([Errno 111] Connection refused)")

2025-02-19 11:26:13,557 ERROR scheduler Exception in Enqueue Events for Site erp-psd-demo
Traceback (most recent call last):
  File "env/lib/python3.10/site-packages/pymysql/connections.py", line 649, in connect
    sock = socket.create_connection(
  File "/usr/lib/python3.10/socket.py", line 857, in create_connection
    raise err
  File "/usr/lib/python3.10/socket.py", line 845, in create_connection
    sock.connect(sa)
ConnectionRefusedError: [Errno 111] Connection refused

During handling of the above exception, another exception occurred:

Traceback (most recent call last):
  File "apps/frappe/frappe/utils/scheduler.py", line 75, in enqueue_events_for_site
    if is_scheduler_inactive():
  File "apps/frappe/frappe/utils/scheduler.py", line 119, in is_scheduler_inactive
    if is_scheduler_disabled(verbose=verbose):
  File "apps/frappe/frappe/utils/scheduler.py", line 132, in is_scheduler_disabled
    frappe.db.get_single_value("System Settings", "enable_scheduler")
  File "apps/frappe/frappe/database/database.py", line 859, in get_single_value
    ).run()
  File "apps/frappe/frappe/query_builder/utils.py", line 87, in execute_query
    result = frappe.db.sql(query, params, *args, **kwargs)  # nosemgrep
  File "apps/frappe/frappe/database/database.py", line 221, in sql
    self.connect()
  File "apps/frappe/frappe/database/database.py", line 126, in connect
    self._conn: "MariadbConnection" | "PostgresConnection" = self.get_connection()
  File "apps/frappe/frappe/database/mariadb/database.py", line 103, in get_connection
    conn = self._get_connection()
  File "apps/frappe/frappe/database/mariadb/database.py", line 109, in _get_connection
    return self.create_connection()
  File "apps/frappe/frappe/database/mariadb/database.py", line 112, in create_connection
    return pymysql.connect(**self.get_connection_settings())
  File "env/lib/python3.10/site-packages/pymysql/connections.py", line 361, in __init__
    self.connect()
  File "env/lib/python3.10/site-packages/pymysql/connections.py", line 716, in connect
    raise exc
pymysql.err.OperationalError: (2003, "Can't connect to MySQL server on '127.0.0.1' ([Errno 111] Connection refused)")

2025-02-19 11:27:13,629 ERROR scheduler Exception in Enqueue Events for Site erp-psd-demo
Traceback (most recent call last):
  File "env/lib/python3.10/site-packages/pymysql/connections.py", line 649, in connect
    sock = socket.create_connection(
  File "/usr/lib/python3.10/socket.py", line 857, in create_connection
    raise err
  File "/usr/lib/python3.10/socket.py", line 845, in create_connection
    sock.connect(sa)
ConnectionRefusedError: [Errno 111] Connection refused

During handling of the above exception, another exception occurred:

Traceback (most recent call last):
  File "apps/frappe/frappe/utils/scheduler.py", line 75, in enqueue_events_for_site
    if is_scheduler_inactive():
  File "apps/frappe/frappe/utils/scheduler.py", line 119, in is_scheduler_inactive
    if is_scheduler_disabled(verbose=verbose):
  File "apps/frappe/frappe/utils/scheduler.py", line 132, in is_scheduler_disabled
    frappe.db.get_single_value("System Settings", "enable_scheduler")
  File "apps/frappe/frappe/database/database.py", line 859, in get_single_value
    ).run()
  File "apps/frappe/frappe/query_builder/utils.py", line 87, in execute_query
    result = frappe.db.sql(query, params, *args, **kwargs)  # nosemgrep
  File "apps/frappe/frappe/database/database.py", line 221, in sql
    self.connect()
  File "apps/frappe/frappe/database/database.py", line 126, in connect
    self._conn: "MariadbConnection" | "PostgresConnection" = self.get_connection()
  File "apps/frappe/frappe/database/mariadb/database.py", line 103, in get_connection
    conn = self._get_connection()
  File "apps/frappe/frappe/database/mariadb/database.py", line 109, in _get_connection
    return self.create_connection()
  File "apps/frappe/frappe/database/mariadb/database.py", line 112, in create_connection
    return pymysql.connect(**self.get_connection_settings())
  File "env/lib/python3.10/site-packages/pymysql/connections.py", line 361, in __init__
    self.connect()
  File "env/lib/python3.10/site-packages/pymysql/connections.py", line 716, in connect
    raise exc
pymysql.err.OperationalError: (2003, "Can't connect to MySQL server on '127.0.0.1' ([Errno 111] Connection refused)")

2025-02-19 11:28:13,732 ERROR scheduler Exception in Enqueue Events for Site erp-psd-demo
Traceback (most recent call last):
  File "env/lib/python3.10/site-packages/pymysql/connections.py", line 649, in connect
    sock = socket.create_connection(
  File "/usr/lib/python3.10/socket.py", line 857, in create_connection
    raise err
  File "/usr/lib/python3.10/socket.py", line 845, in create_connection
    sock.connect(sa)
ConnectionRefusedError: [Errno 111] Connection refused

During handling of the above exception, another exception occurred:

Traceback (most recent call last):
  File "apps/frappe/frappe/utils/scheduler.py", line 75, in enqueue_events_for_site
    if is_scheduler_inactive():
  File "apps/frappe/frappe/utils/scheduler.py", line 119, in is_scheduler_inactive
    if is_scheduler_disabled(verbose=verbose):
  File "apps/frappe/frappe/utils/scheduler.py", line 132, in is_scheduler_disabled
    frappe.db.get_single_value("System Settings", "enable_scheduler")
  File "apps/frappe/frappe/database/database.py", line 859, in get_single_value
    ).run()
  File "apps/frappe/frappe/query_builder/utils.py", line 87, in execute_query
    result = frappe.db.sql(query, params, *args, **kwargs)  # nosemgrep
  File "apps/frappe/frappe/database/database.py", line 221, in sql
    self.connect()
  File "apps/frappe/frappe/database/database.py", line 126, in connect
    self._conn: "MariadbConnection" | "PostgresConnection" = self.get_connection()
  File "apps/frappe/frappe/database/mariadb/database.py", line 103, in get_connection
    conn = self._get_connection()
  File "apps/frappe/frappe/database/mariadb/database.py", line 109, in _get_connection
    return self.create_connection()
  File "apps/frappe/frappe/database/mariadb/database.py", line 112, in create_connection
    return pymysql.connect(**self.get_connection_settings())
  File "env/lib/python3.10/site-packages/pymysql/connections.py", line 361, in __init__
    self.connect()
  File "env/lib/python3.10/site-packages/pymysql/connections.py", line 716, in connect
    raise exc
pymysql.err.OperationalError: (2003, "Can't connect to MySQL server on '127.0.0.1' ([Errno 111] Connection refused)")

